Workbook

Sheet Сводка
A1: Исходы сделок в пунктах: выгоднейшие параметры каждой стратегии
A2: Лист на каждую пару «стратегия × актив»: исходы по порядку, плюс — прибыль, минус — убыток.
A3: Пункт — единица котировки: BR — 1 USD за баррель, NG — 1 USD за MMBtu; шаг цены — 0.01 (BR) и 0.001 (NG).
A4: Семь семейств: размер позиции меняется, поэтому пункты даны на единицу позиции, а итог — в USD на счёт 1 000 000. Скользящие средние: 1 контракт, пункты складываются.
A5: Все числа на этом листе — формулы по листам таблиц.
A7: Лист | B7: Стратегия | C7: Актив | D7: Параметры | E7: Исходов | F7: Прибыльных | G7: Убыточных | H7: Доля прибыльных | I7: Средний прибыльный, пунктов | J7: Средний убыточный, пунктов | K7: Лучший, пунктов | L7: Худший, пунктов | M7: Макс. убыточных подряд | N7: Итог IS, USD | O7: Итог OOS, USD | P7: Итог, USD
A8: 7F_1_TSMOM_BR | B8: 1 Time-Series Momentum | C8: BR | D8: lookback=40 | E8: =COUNTIFS(7F_1_TSMOM_BR!$C$6:$C$351,"<>") -> 344 | F8: =COUNTIFS(7F_1_TSMOM_BR!$J$6:$J$351,">0",7F_1_TSMOM_BR!$C$6:$C$351,"<>") -> 163 | G8: =COUNTIFS(7F_1_TSMOM_BR!$J$6:$J$351,"<0",7F_1_TSMOM_BR!$C$6:$C$351,"<>") -> 181 | H8: =IF(E8>0,F8/E8,0) -> 0.47383721 | I8: =IFERROR(AVERAGEIFS(7F_1_TSMOM_BR!$J$6:$J$351,7F_1_TSMOM_BR!$J$6:$J$351,">0",7F_1_TSMOM_BR!$C$6:$C$351,"<>"),0) -> 7.5499368 | J8: =IFERROR(AVERAGEIFS(7F_1_TSMOM_BR!$J$6:$J$351,7F_1_TSMOM_BR!$J$6:$J$351,"<0",7F_1_TSMOM_BR!$C$6:$C$351,"<>"),0) -> -1.9171807 | K8: =_xlfn.MAXIFS(7F_1_TSMOM_BR!$J$6:$J$351,7F_1_TSMOM_BR!$C$6:$C$351,"<>") -> 47.59889 | L8: =_xlfn.MINIFS(7F_1_TSMOM_BR!$J$6:$J$351,7F_1_TSMOM_BR!$C$6:$C$351,"<>") -> -12.5317 | M8: =MAX(7F_1_TSMOM_BR!$L$6:$L$351) -> 13 | N8: =SUMIFS(7F_1_TSMOM_BR!$N$6:$N$351,7F_1_TSMOM_BR!$B$6:$B$351,"IS") -> 1313343.6 | O8: =SUMIFS(7F_1_TSMOM_BR!$N$6:$N$351,7F_1_TSMOM_BR!$B$6:$B$351,"OOS") -> 171453.46 | P8: =SUM(7F_1_TSMOM_BR!$N$6:$N$351) -> 1484797.1
A9: 7F_1_TSMOM_NG | B9: 1 Time-Series Momentum | C9: NG | D9: lookback=90 | E9: =COUNTIFS(7F_1_TSMOM_NG!$C$6:$C$124,"<>") -> 117 | F9: =COUNTIFS(7F_1_TSMOM_NG!$J$6:$J$124,">0",7F_1_TSMOM_NG!$C$6:$C$124,"<>") -> 56 | G9: =COUNTIFS(7F_1_TSMOM_NG!$J$6:$J$124,"<0",7F_1_TSMOM_NG!$C$6:$C$124,"<>") -> 61 | H9: =IF(E9>0,F9/E9,0) -> 0.47863248 | I9: =IFERROR(AVERAGEIFS(7F_1_TSMOM_NG!$J$6:$J$124,7F_1_TSMOM_NG!$J$6:$J$124,">0",7F_1_TSMOM_NG!$C$6:$C$124,"<>"),0) -> 0.76030964 | J9: =IFERROR(AVERAGEIFS(7F_1_TSMOM_NG!$J$6:$J$124,7F_1_TSMOM_NG!$J$6:$J$124,"<0",7F_1_TSMOM_NG!$C$6:$C$124,"<>"),0) -> -0.2203018 | K9: =_xlfn.MAXIFS(7F_1_TSMOM_NG!$J$6:$J$124,7F_1_TSMOM_NG!$C$6:$C$124,"<>") -> 2.8299 | L9: =_xlfn.MINIFS(7F_1_TSMOM_NG!$J$6:$J$124,7F_1_TSMOM_NG!$C$6:$C$124,"<>") -> -1.20222 | M9: =MAX(7F_1_TSMOM_NG!$L$6:$L$124) -> 7 | N9: =SUMIFS(7F_1_TSMOM_NG!$N$6:$N$124,7F_1_TSMOM_NG!$B$6:$B$124,"IS") -> 444988.74 | O9: =SUMIFS(7F_1_TSMOM_NG!$N$6:$N$124,7F_1_TSMOM_NG!$B$6:$B$124,"OOS") -> -181099.69 | P9: =SUM(7F_1_TSMOM_NG!$N$6:$N$124) -> 263889.05
A10: 7F_2_DualMA_BR | B10: 2 Dual Moving Average | C10: BR | D10: fast=20,slow=60 | E10: =COUNTIFS(7F_2_DualMA_BR!$C$6:$C$179,"<>") -> 172 | F10: =COUNTIFS(7F_2_DualMA_BR!$J$6:$J$179,">0",7F_2_DualMA_BR!$C$6:$C$179,"<>") -> 107 | G10: =COUNTIFS(7F_2_DualMA_BR!$J$6:$J$179,"<0",7F_2_DualMA_BR!$C$6:$C$179,"<>") -> 65 | H10: =IF(E10>0,F10/E10,0) -> 0.62209302 | I10: =IFERROR(AVERAGEIFS(7F_2_DualMA_BR!$J$6:$J$179,7F_2_DualMA_BR!$J$6:$J$179,">0",7F_2_DualMA_BR!$C$6:$C$179,"<>"),0) -> 10.943166 | J10: =IFERROR(AVERAGEIFS(7F_2_DualMA_BR!$J$6:$J$179,7F_2_DualMA_BR!$J$6:$J$179,"<0",7F_2_DualMA_BR!$C$6:$C$179,"<>"),0) -> -3.3440445 | K10: =_xlfn.MAXIFS(7F_2_DualMA_BR!$J$6:$J$179,7F_2_DualMA_BR!$C$6:$C$179,"<>") -> 45.61922 | L10: =_xlfn.MINIFS(7F_2_DualMA_BR!$J$6:$J$179,7F_2_DualMA_BR!$C$6:$C$179,"<>") -> -12.06012 | M10: =MAX(7F_2_DualMA_BR!$L$6:$L$179) -> 8 | N10: =SUMIFS(7F_2_DualMA_BR!$N$6:$N$179,7F_2_DualMA_BR!$B$6:$B$179,"IS") -> 1412319.4 | O10: =SUMIFS(7F_2_DualMA_BR!$N$6:$N$179,7F_2_DualMA_BR!$B$6:$B$179,"OOS") -> 565401.18 | P10: =SUM(7F_2_DualMA_BR!$N$6:$N$179) -> 1977720.6
A11: 7F_2_DualMA_NG | B11: 2 Dual Moving Average | C11: NG | D11: fast=20,slow=150 | E11: =COUNTIFS(7F_2_DualMA_NG!$C$6:$C$67,"<>") -> 60 | F11: =COUNTIFS(7F_2_DualMA_NG!$J$6:$J$67,">0",7F_2_DualMA_NG!$C$6:$C$67,"<>") -> 37 | G11: =COUNTIFS(7F_2_DualMA_NG!$J$6:$J$67,"<0",7F_2_DualMA_NG!$C$6:$C$67,"<>") -> 23 | H11: =IF(E11>0,F11/E11,0) -> 0.61666667 | I11: =IFERROR(AVERAGEIFS(7F_2_DualMA_NG!$J$6:$J$67,7F_2_DualMA_NG!$J$6:$J$67,">0",7F_2_DualMA_NG!$C$6:$C$67,"<>"),0) -> 0.85782351 | J11: =IFERROR(AVERAGEIFS(7F_2_DualMA_NG!$J$6:$J$67,7F_2_DualMA_NG!$J$6:$J$67,"<0",7F_2_DualMA_NG!$C$6:$C$67,"<>"),0) -> -0.63211304 | K11: =_xlfn.MAXIFS(7F_2_DualMA_NG!$J$6:$J$67,7F_2_DualMA_NG!$C$6:$C$67,"<>") -> 2.61319 | L11: =_xlfn.MINIFS(7F_2_DualMA_NG!$J$6:$J$67,7F_2_DualMA_NG!$C$6:$C$67,"<>") -> -2.24522 | M11: =MAX(7F_2_DualMA_NG!$L$6:$L$67) -> 6 | N11: =SUMIFS(7F_2_DualMA_NG!$N$6:$N$67,7F_2_DualMA_NG!$B$6:$B$67,"IS") -> 376022.5 | O11: =SUMIFS(7F_2_DualMA_NG!$N$6:$N$67,7F_2_DualMA_NG!$B$6:$B$67,"OOS") -> -162323.53 | P11: =SUM(7F_2_DualMA_NG!$N$6:$N$67) -> 213698.97
A12: 7F_3_Breakout_BR | B12: 3 Channel Breakout | C12: BR | D12: entry=40,exit_=20 | E12: =COUNTIFS(7F_3_Breakout_BR!$C$6:$C$133,"<>") -> 126 | F12: =COUNTIFS(7F_3_Breakout_BR!$J$6:$J$133,">0",7F_3_Breakout_BR!$C$6:$C$133,"<>") -> 87 | G12: =COUNTIFS(7F_3_Breakout_BR!$J$6:$J$133,"<0",7F_3_Breakout_BR!$C$6:$C$133,"<>") -> 39 | H12: =IF(E12>0,F12/E12,0) -> 0.69047619 | I12: =IFERROR(AVERAGEIFS(7F_3_Breakout_BR!$J$6:$J$133,7F_3_Breakout_BR!$J$6:$J$133,">0",7F_3_Breakout_BR!$C$6:$C$133,"<>"),0) -> 11.046735 | J12: =IFERROR(AVERAGEIFS(7F_3_Breakout_BR!$J$6:$J$133,7F_3_Breakout_BR!$J$6:$J$133,"<0",7F_3_Breakout_BR!$C$6:$C$133,"<>"),0) -> -3.1924421 | K12: =_xlfn.MAXIFS(7F_3_Breakout_BR!$J$6:$J$133,7F_3_Breakout_BR!$C$6:$C$133,"<>") -> 45.53858 | L12: =_xlfn.MINIFS(7F_3_Breakout_BR!$J$6:$J$133,7F_3_Breakout_BR!$C$6:$C$133,"<>") -> -7.74989 | M12: =MAX(7F_3_Breakout_BR!$L$6:$L$133) -> 7 | N12: =SUMIFS(7F_3_Breakout_BR!$N$6:$N$133,7F_3_Breakout_BR!$B$6:$B$133,"IS") -> 1593924 | O12: =SUMIFS(7F_3_Breakout_BR!$N$6:$N$133,7F_3_Breakout_BR!$B$6:$B$133,"OOS") -> 494872.3 | P12: =SUM(7F_3_Breakout_BR!$N$6:$N$133) -> 2088796.3
A13: 7F_3_Breakout_NG | B13: 3 Channel Breakout | C13: NG | D13: entry=20,exit_=10 | E13: =COUNTIFS(7F_3_Breakout_NG!$C$6:$C$82,"<>") -> 75 | F13: =COUNTIFS(7F_3_Breakout_NG!$J$6:$J$82,">0",7F_3_Breakout_NG!$C$6:$C$82,"<>") -> 46 | G13: =COUNTIFS(7F_3_Breakout_NG!$J$6:$J$82,"<0",7F_3_Breakout_NG!$C$6:$C$82,"<>") -> 29 | H13: =IF(E13>0,F13/E13,0) -> 0.61333333 | I13: =IFERROR(AVERAGEIFS(7F_3_Breakout_NG!$J$6:$J$82,7F_3_Breakout_NG!$J$6:$J$82,">0",7F_3_Breakout_NG!$C$6:$C$82,"<>"),0) -> 0.59741065 | J13: =IFERROR(AVERAGEIFS(7F_3_Breakout_NG!$J$6:$J$82,7F_3_Breakout_NG!$J$6:$J$82,"<0",7F_3_Breakout_NG!$C$6:$C$82,"<>"),0) -> -0.38291172 | K13: =_xlfn.MAXIFS(7F_3_Breakout_NG!$J$6:$J$82,7F_3_Breakout_NG!$C$6:$C$82,"<>") -> 2.26116 | L13: =_xlfn.MINIFS(7F_3_Breakout_NG!$J$6:$J$82,7F_3_Breakout_NG!$C$6:$C$82,"<>") -> -1.56395 | M13: =MAX(7F_3_Breakout_NG!$L$6:$L$82) -> 6 | N13: =SUMIFS(7F_3_Breakout_NG!$N$6:$N$82,7F_3_Breakout_NG!$B$6:$B$82,"IS") -> 374185.26 | O13: =SUMIFS(7F_3_Breakout_NG!$N$6:$N$82,7F_3_Breakout_NG!$B$6:$B$82,"OOS") -> -54643.81 | P13: =SUM(7F_3_Breakout_NG!$N$6:$N$82) -> 319541.45
A14: 7F_4_CrossSect_NGBR_NG | B14: 4 Cross-sectional momentum | C14: NG | D14: lookback=120 | E14: =COUNTIFS(7F_4_CrossSect_NGBR_NG!$C$6:$C$127,"<>") -> 120 | F14: =COUNTIFS(7F_4_CrossSect_NGBR_NG!$J$6:$J$127,">0",7F_4_CrossSect_NGBR_NG!$C$6:$C$127,"<>") -> 62 | G14: =COUNTIFS(7F_4_CrossSect_NGBR_NG!$J$6:$J$127,"<0",7F_4_CrossSect_NGBR_NG!$C$6:$C$127,"<>") -> 58 | H14: =IF(E14>0,F14/E14,0) -> 0.51666667 | I14: =IFERROR(AVERAGEIFS(7F_4_CrossSect_NGBR_NG!$J$6:$J$127,7F_4_CrossSect_NGBR_NG!$J$6:$J$127,">0",7F_4_CrossSect_NGBR_NG!$C$6:$C$127,"<>"),0) -> 0.46579097 | J14: =IFERROR(AVERAGEIFS(7F_4_CrossSect_NGBR_NG!$J$6:$J$127,7F_4_CrossSect_NGBR_NG!$J$6:$J$127,"<0",7F_4_CrossSect_NGBR_NG!$C$6:$C$127,"<>"),0) -> -0.52460983 | K14: =_xlfn.MAXIFS(7F_4_CrossSect_NGBR_NG!$J$6:$J$127,7F_4_CrossSect_NGBR_NG!$C$6:$C$127,"<>") -> 2.8299 | L14: =_xlfn.MINIFS(7F_4_CrossSect_NGBR_NG!$J$6:$J$127,7F_4_CrossSect_NGBR_NG!$C$6:$C$127,"<>") -> -3.31334 | M14: =MAX(7F_4_CrossSect_NGBR_NG!$L$6:$L$127) -> 11 | N14: =SUMIFS(7F_4_CrossSect_NGBR_NG!$N$6:$N$127,7F_4_CrossSect_NGBR_NG!$B$6:$B$127,"IS") -> -69045.62 | O14: =SUMIFS(7F_4_CrossSect_NGBR_NG!$N$6:$N$127,7F_4_CrossSect_NGBR_NG!$B$6:$B$127,"OOS") -> -33836.19 | P14: =SUM(7F_4_CrossSect_NGBR_NG!$N$6:$N$127) -> -102881.81
A15: 7F_4_CrossSect_NGBR_BR | B15: 4 Cross-sectional momentum | C15: BR | D15: lookback=120 | E15: =COUNTIFS(7F_4_CrossSect_NGBR_BR!$C$6:$C$115,"<>") -> 108 | F15: =COUNTIFS(7F_4_CrossSect_NGBR_BR!$J$6:$J$115,">0",7F_4_CrossSect_NGBR_BR!$C$6:$C$115,"<>") -> 41 | G15: =COUNTIFS(7F_4_CrossSect_NGBR_BR!$J$6:$J$115,"<0",7F_4_CrossSect_NGBR_BR!$C$6:$C$115,"<>") -> 67 | H15: =IF(E15>0,F15/E15,0) -> 0.37962963 | I15: =IFERROR(AVERAGEIFS(7F_4_CrossSect_NGBR_BR!$J$6:$J$115,7F_4_CrossSect_NGBR_BR!$J$6:$J$115,">0",7F_4_CrossSect_NGBR_BR!$C$6:$C$115,"<>"),0) -> 8.7519302 | J15: =IFERROR(AVERAGEIFS(7F_4_CrossSect_NGBR_BR!$J$6:$J$115,7F_4_CrossSect_NGBR_BR!$J$6:$J$115,"<0",7F_4_CrossSect_NGBR_BR!$C$6:$C$115,"<>"),0) -> -5.2077742 | K15: =_xlfn.MAXIFS(7F_4_CrossSect_NGBR_BR!$J$6:$J$115,7F_4_CrossSect_NGBR_BR!$C$6:$C$115,"<>") -> 48.61281 | L15: =_xlfn.MINIFS(7F_4_CrossSect_NGBR_BR!$J$6:$J$115,7F_4_CrossSect_NGBR_BR!$C$6:$C$115,"<>") -> -39.47487 | M15: =MAX(7F_4_CrossSect_NGBR_BR!$L$6:$L$115) -> 8 | N15: =SUMIFS(7F_4_CrossSect_NGBR_BR!$N$6:$N$115,7F_4_CrossSect_NGBR_BR!$B$6:$B$115,"IS") -> 256611.36 | O15: =SUMIFS(7F_4_CrossSect_NGBR_BR!$N$6:$N$115,7F_4_CrossSect_NGBR_BR!$B$6:$B$115,"OOS") -> -274886.67 | P15: =SUM(7F_4_CrossSect_NGBR_BR!$N$6:$N$115) -> -18275.31
A16: 7F_5_Carry_BR | B16: 5 Carry / term structure | C16: BR | D16: smooth=1,threshold=0.15 | E16: =COUNTIFS(7F_5_Carry_BR!$C$6:$C$135,"<>") -> 130 | F16: =COUNTIFS(7F_5_Carry_BR!$J$6:$J$135,">0",7F_5_Carry_BR!$C$6:$C$135,"<>") -> 73 | G16: =COUNTIFS(7F_5_Carry_BR!$J$6:$J$135,"<0",7F_5_Carry_BR!$C$6:$C$135,"<>") -> 57 | H16: =IF(E16>0,F16/E16,0) -> 0.56153846 | I16: =IFERROR(AVERAGEIFS(7F_5_Carry_BR!$J$6:$J$135,7F_5_Carry_BR!$J$6:$J$135,">0",7F_5_Carry_BR!$C$6:$C$135,"<>"),0) -> 9.46589 | J16: =IFERROR(AVERAGEIFS(7F_5_Carry_BR!$J$6:$J$135,7F_5_Carry_BR!$J$6:$J$135,"<0",7F_5_Carry_BR!$C$6:$C$135,"<>"),0) -> -5.7827382 | K16: =_xlfn.MAXIFS(7F_5_Carry_BR!$J$6:$J$135,7F_5_Carry_BR!$C$6:$C$135,"<>") -> 39.76593 | L16: =_xlfn.MINIFS(7F_5_Carry_BR!$J$6:$J$135,7F_5_Carry_BR!$C$6:$C$135,"<>") -> -33.12239 | M16: =MAX(7F_5_Carry_BR!$L$6:$L$135) -> 7 | N16: =SUMIFS(7F_5_Carry_BR!$N$6:$N$135,7F_5_Carry_BR!$B$6:$B$135,"IS") -> 1158861.3 | O16: =SUMIFS(7F_5_Carry_BR!$N$6:$N$135,7F_5_Carry_BR!$B$6:$B$135,"OOS") -> 366498.23 | P16: =SUM(7F_5_Carry_BR!$N$6:$N$135) -> 1525359.5
A17: 7F_5_Carry_NG | B17: 5 Carry / term structure | C17: NG | D17: smooth=1,threshold=0.15 | E17: =COUNTIFS(7F_5_Carry_NG!$C$6:$C$84,"<>") -> 77 | F17: =COUNTIFS(7F_5_Carry_NG!$J$6:$J$84,">0",7F_5_Carry_NG!$C$6:$C$84,"<>") -> 43 | G17: =COUNTIFS(7F_5_Carry_NG!$J$6:$J$84,"<0",7F_5_Carry_NG!$C$6:$C$84,"<>") -> 34 | H17: =IF(E17>0,F17/E17,0) -> 0.55844156 | I17: =IFERROR(AVERAGEIFS(7F_5_Carry_NG!$J$6:$J$84,7F_5_Carry_NG!$J$6:$J$84,">0",7F_5_Carry_NG!$C$6:$C$84,"<>"),0) -> 0.6180014 | J17: =IFERROR(AVERAGEIFS(7F_5_Carry_NG!$J$6:$J$84,7F_5_Carry_NG!$J$6:$J$84,"<0",7F_5_Carry_NG!$C$6:$C$84,"<>"),0) -> -0.68661059 | K17: =_xlfn.MAXIFS(7F_5_Carry_NG!$J$6:$J$84,7F_5_Carry_NG!$C$6:$C$84,"<>") -> 2.87612 | L17: =_xlfn.MINIFS(7F_5_Carry_NG!$J$6:$J$84,7F_5_Carry_NG!$C$6:$C$84,"<>") -> -2.13428 | M17: =MAX(7F_5_Carry_NG!$L$6:$L$84) -> 8 | N17: =SUMIFS(7F_5_Carry_NG!$N$6:$N$84,7F_5_Carry_NG!$B$6:$B$84,"IS") -> -146662.01 | O17: =SUMIFS(7F_5_Carry_NG!$N$6:$N$84,7F_5_Carry_NG!$B$6:$B$84,"OOS") -> 247828.52 | P17: =SUM(7F_5_Carry_NG!$N$6:$N$84) -> 101166.51
A18: 7F_6_PortfolioMA_NGBR_NG | B18: 6 MA + portfolio | C18: NG | D18: fast=20,slow=100 | E18: =COUNTIFS(7F_6_PortfolioMA_NGBR_NG!$C$6:$C$73,"<>") -> 66 | F18: =COUNTIFS(7F_6_PortfolioMA_NGBR_NG!$J$6:$J$73,">0",7F_6_PortfolioMA_NGBR_NG!$C$6:$C$73,"<>") -> 38 | G18: =COUNTIFS(7F_6_PortfolioMA_NGBR_NG!$J$6:$J$73,"<0",7F_6_PortfolioMA_NGBR_NG!$C$6:$C$73,"<>") -> 28 | H18: =IF(E18>0,F18/E18,0) -> 0.57575758 | I18: =IFERROR(AVERAGEIFS(7F_6_PortfolioMA_NGBR_NG!$J$6:$J$73,7F_6_PortfolioMA_NGBR_NG!$J$6:$J$73,">0",7F_6_PortfolioMA_NGBR_NG!$C$6:$C$73,"<>"),0) -> 0.89213474 | J18: =IFERROR(AVERAGEIFS(7F_6_PortfolioMA_NGBR_NG!$J$6:$J$73,7F_6_PortfolioMA_NGBR_NG!$J$6:$J$73,"<0",7F_6_PortfolioMA_NGBR_NG!$C$6:$C$73,"<>"),0) -> -0.66233 | K18: =_xlfn.MAXIFS(7F_6_PortfolioMA_NGBR_NG!$J$6:$J$73,7F_6_PortfolioMA_NGBR_NG!$C$6:$C$73,"<>") -> 2.68859 | L18: =_xlfn.MINIFS(7F_6_PortfolioMA_NGBR_NG!$J$6:$J$73,7F_6_PortfolioMA_NGBR_NG!$C$6:$C$73,"<>") -> -2.38076 | M18: =MAX(7F_6_PortfolioMA_NGBR_NG!$L$6:$L$73) -> 6 | N18: =SUMIFS(7F_6_PortfolioMA_NGBR_NG!$N$6:$N$73,7F_6_PortfolioMA_NGBR_NG!$B$6:$B$73,"IS") -> 170539.33 | O18: =SUMIFS(7F_6_PortfolioMA_NGBR_NG!$N$6:$N$73,7F_6_PortfolioMA_NGBR_NG!$B$6:$B$73,"OOS") -> -85478.09 | P18: =SUM(7F_6_PortfolioMA_NGBR_NG!$N$6:$N$73) -> 85061.24
A19: 7F_6_PortfolioMA_NGBR_BR | B19: 6 MA + portfolio | C19: BR | D19: fast=20,slow=100 | E19: =COUNTIFS(7F_6_PortfolioMA_NGBR_BR!$C$6:$C$70,"<>") -> 63 | F19: =COUNTIFS(7F_6_PortfolioMA_NGBR_BR!$J$6:$J$70,">0",7F_6_PortfolioMA_NGBR_BR!$C$6:$C$70,"<>") -> 43 | G19: =COUNTIFS(7F_6_PortfolioMA_NGBR_BR!$J$6:$J$70,"<0",7F_6_PortfolioMA_NGBR_BR!$C$6:$C$70,"<>") -> 20 | H19: =IF(E19>0,F19/E19,0) -> 0.68253968 | I19: =IFERROR(AVERAGEIFS(7F_6_PortfolioMA_NGBR_BR!$J$6:$J$70,7F_6_PortfolioMA_NGBR_BR!$J$6:$J$70,">0",7F_6_PortfolioMA_NGBR_BR!$C$6:$C$70,"<>"),0) -> 12.803369 | J19: =IFERROR(AVERAGEIFS(7F_6_PortfolioMA_NGBR_BR!$J$6:$J$70,7F_6_PortfolioMA_NGBR_BR!$J$6:$J$70,"<0",7F_6_PortfolioMA_NGBR_BR!$C$6:$C$70,"<>"),0) -> -4.742797 | K19: =_xlfn.MAXIFS(7F_6_PortfolioMA_NGBR_BR!$J$6:$J$70,7F_6_PortfolioMA_NGBR_BR!$C$6:$C$70,"<>") -> 44.83664 | L19: =_xlfn.MINIFS(7F_6_PortfolioMA_NGBR_BR!$J$6:$J$70,7F_6_PortfolioMA_NGBR_BR!$C$6:$C$70,"<>") -> -10.30961 | M19: =MAX(7F_6_PortfolioMA_NGBR_BR!$L$6:$L$70) -> 6 | N19: =SUMIFS(7F_6_PortfolioMA_NGBR_BR!$N$6:$N$70,7F_6_PortfolioMA_NGBR_BR!$B$6:$B$70,"IS") -> 384249.4 | O19: =SUMIFS(7F_6_PortfolioMA_NGBR_BR!$N$6:$N$70,7F_6_PortfolioMA_NGBR_BR!$B$6:$B$70,"OOS") -> -33561.8 | P19: =SUM(7F_6_PortfolioMA_NGBR_BR!$N$6:$N$70) -> 350687.6
A20: 7F_7_MomRev_BR | B20: 7 Momentum + reversal | C20: BR | D20: momentum=60,reversal=750 | E20: =COUNTIFS(7F_7_MomRev_BR!$C$6:$C$194,"<>") -> 188 | F20: =COUNTIFS(7F_7_MomRev_BR!$J$6:$J$194,">0",7F_7_MomRev_BR!$C$6:$C$194,"<>") -> 95 | G20: =COUNTIFS(7F_7_MomRev_BR!$J$6:$J$194,"<0",7F_7_MomRev_BR!$C$6:$C$194,"<>") -> 93 | H20: =IF(E20>0,F20/E20,0) -> 0.50531915 | I20: =IFERROR(AVERAGEIFS(7F_7_MomRev_BR!$J$6:$J$194,7F_7_MomRev_BR!$J$6:$J$194,">0",7F_7_MomRev_BR!$C$6:$C$194,"<>"),0) -> 6.7994085 | J20: =IFERROR(AVERAGEIFS(7F_7_MomRev_BR!$J$6:$J$194,7F_7_MomRev_BR!$J$6:$J$194,"<0",7F_7_MomRev_BR!$C$6:$C$194,"<>"),0) -> -1.9160204 | K20: =_xlfn.MAXIFS(7F_7_MomRev_BR!$J$6:$J$194,7F_7_MomRev_BR!$C$6:$C$194,"<>") -> 42.19073 | L20: =_xlfn.MINIFS(7F_7_MomRev_BR!$J$6:$J$194,7F_7_MomRev_BR!$C$6:$C$194,"<>") -> -8.68317 | M20: =MAX(7F_7_MomRev_BR!$L$6:$L$194) -> 9 | N20: =SUMIFS(7F_7_MomRev_BR!$N$6:$N$194,7F_7_MomRev_BR!$B$6:$B$194,"IS") -> 540268.73 | O20: =SUMIFS(7F_7_MomRev_BR!$N$6:$N$194,7F_7_MomRev_BR!$B$6:$B$194,"OOS") -> 19125.88 | P20: =SUM(7F_7_MomRev_BR!$N$6:$N$194) -> 559394.61
A21: 7F_7_MomRev_NG | B21: 7 Momentum + reversal | C21: NG | D21: momentum=60,reversal=500 | E21: =COUNTIFS(7F_7_MomRev_NG!$C$6:$C$126,"<>") -> 120 | F21: =COUNTIFS(7F_7_MomRev_NG!$J$6:$J$126,">0",7F_7_MomRev_NG!$C$6:$C$126,"<>") -> 57 | G21: =COUNTIFS(7F_7_MomRev_NG!$J$6:$J$126,"<0",7F_7_MomRev_NG!$C$6:$C$126,"<>") -> 63 | H21: =IF(E21>0,F21/E21,0) -> 0.475 | I21: =IFERROR(AVERAGEIFS(7F_7_MomRev_NG!$J$6:$J$126,7F_7_MomRev_NG!$J$6:$J$126,">0",7F_7_MomRev_NG!$C$6:$C$126,"<>"),0) -> 0.43404895 | J21: =IFERROR(AVERAGEIFS(7F_7_MomRev_NG!$J$6:$J$126,7F_7_MomRev_NG!$J$6:$J$126,"<0",7F_7_MomRev_NG!$C$6:$C$126,"<>"),0) -> -0.21724635 | K21: =_xlfn.MAXIFS(7F_7_MomRev_NG!$J$6:$J$126,7F_7_MomRev_NG!$C$6:$C$126,"<>") -> 2.64912 | L21: =_xlfn.MINIFS(7F_7_MomRev_NG!$J$6:$J$126,7F_7_MomRev_NG!$C$6:$C$126,"<>") -> -1.96503 | M21: =MAX(7F_7_MomRev_NG!$L$6:$L$126) -> 8 | N21: =SUMIFS(7F_7_MomRev_NG!$N$6:$N$126,7F_7_MomRev_NG!$B$6:$B$126,"IS") -> 7851.05 | O21: =SUMIFS(7F_7_MomRev_NG!$N$6:$N$126,7F_7_MomRev_NG!$B$6:$B$126,"OOS") -> -35111.99 | P21: =SUM(7F_7_MomRev_NG!$N$6:$N$126) -> -27260.94
A22: MA_3_NG_R1 | B22: Пересечение скользящих средних, 5 мин | C22: NG | D22: EMA12 × WMA131, наклон A_pct, выход B_slow_flip | E22: =COUNTIFS(MA_3_NG_R1!$C$6:$C$1072,"<>") -> 1067 | F22: =COUNTIFS(MA_3_NG_R1!$J$6:$J$1072,">0",MA_3_NG_R1!$C$6:$C$1072,"<>") -> 405 | G22: =COUNTIFS(MA_3_NG_R1!$J$6:$J$1072,"<0",MA_3_NG_R1!$C$6:$C$1072,"<>") -> 657 | H22: =IF(E22>0,F22/E22,0) -> 0.37956888 | I22: =IFERROR(AVERAGEIFS(MA_3_NG_R1!$J$6:$J$1072,MA_3_NG_R1!$J$6:$J$1072,">0",MA_3_NG_R1!$C$6:$C$1072,"<>"),0) -> 0.18533333 | J22: =IFERROR(AVERAGEIFS(MA_3_NG_R1!$J$6:$J$1072,MA_3_NG_R1!$J$6:$J$1072,"<0",MA_3_NG_R1!$C$6:$C$1072,"<>"),0) -> -0.078692542 | K22: =_xlfn.MAXIFS(MA_3_NG_R1!$J$6:$J$1072,MA_3_NG_R1!$C$6:$C$1072,"<>") -> 2.473 | L22: =_xlfn.MINIFS(MA_3_NG_R1!$J$6:$J$1072,MA_3_NG_R1!$C$6:$C$1072,"<>") -> -0.721 | M22: =MAX(MA_3_NG_R1!$L$6:$L$1072) -> 9 | N22: =SUMIFS(MA_3_NG_R1!$N$6:$N$1072,MA_3_NG_R1!$B$6:$B$1072,"IS") -> 1818.4 | O22: =SUMIFS(MA_3_NG_R1!$N$6:$N$1072,MA_3_NG_R1!$B$6:$B$1072,"OOS") -> 517.5 | P22: =SUM(MA_3_NG_R1!$N$6:$N$1072) -> 2335.9
A23: MA_3_BR_R1 | B23: Пересечение скользящих средних, 5 мин | C23: BR | D23: TMA10 × SMA23, наклон B_atr, выход B_slow_flip | E23: =COUNTIFS(MA_3_BR_R1!$C$6:$C$6358,"<>") -> 6353 | F23: =COUNTIFS(MA_3_BR_R1!$J$6:$J$6358,">0",MA_3_BR_R1!$C$6:$C$6358,"<>") -> 2316 | G23: =COUNTIFS(MA_3_BR_R1!$J$6:$J$6358,"<0",MA_3_BR_R1!$C$6:$C$6358,"<>") -> 3990 | H23: =IF(E23>0,F23/E23,0) -> 0.36455218 | I23: =IFERROR(AVERAGEIFS(MA_3_BR_R1!$J$6:$J$6358,MA_3_BR_R1!$J$6:$J$6358,">0",MA_3_BR_R1!$C$6:$C$6358,"<>"),0) -> 0.96386442 | J23: =IFERROR(AVERAGEIFS(MA_3_BR_R1!$J$6:$J$6358,MA_3_BR_R1!$J$6:$J$6358,"<0",MA_3_BR_R1!$C$6:$C$6358,"<>"),0) -> -0.46907268 | K23: =_xlfn.MAXIFS(MA_3_BR_R1!$J$6:$J$6358,MA_3_BR_R1!$C$6:$C$6358,"<>") -> 23.34 | L23: =_xlfn.MINIFS(MA_3_BR_R1!$J$6:$J$6358,MA_3_BR_R1!$C$6:$C$6358,"<>") -> -8.06 | M23: =MAX(MA_3_BR_R1!$L$6:$L$6358) -> 17 | N23: =SUMIFS(MA_3_BR_R1!$N$6:$N$6358,MA_3_BR_R1!$B$6:$B$6358,"IS") -> 3357 | O23: =SUMIFS(MA_3_BR_R1!$N$6:$N$6358,MA_3_BR_R1!$B$6:$B$6358,"OOS") -> 250.1 | P23: =SUM(MA_3_BR_R1!$N$6:$N$6358) -> 3607.1

Sheet 7F_1_TSMOM_BR
A1: 1 Time-Series Momentum · BR · lookback=40
A2: Параметры: лучший Шарп в выборке. Издержки ~7 б.п. за оборот вычтены.
A3: Каждая строка — исход по порядку закрытия. Пункт — единица котировки (BR: 1 USD за баррель, NG: 1 USD за MMBtu); плюс — прибыль, минус — убыток.
A5: № | B5: период | C5: вход | D5: выход | E5: направление | F5: объём, ед. актива | G5: цена входа | H5: цена выхода | I5: через ролл | J5: результат, пунктов | K5: исход | L5: серия убыточных подряд | M5: результат, шагов цены | N5: результат, USD | O5: итог, USD | P5: примечание
A6: 1 | B6: IS | C6: 2012-02-15 | D6: 2012-03-02 | E6: long | F6: 2915.5 | G6: 118.0831 | H6: 125.9037 | I6: да | J6: 6.97414 | K6: =IF(J6>0,"прибыль",IF(J6<0,"убыток","ноль")) -> прибыль | L6: =IF(AND(C6<>"",J6<0),1,0) -> 0 | M6: 697.41 | N6: 20333.08 | O6: 20333.08
A7: 2 | B7: IS | C7: 2012-03-02 | D7: 2012-04-11 | E7: long | F7: 6671.22 | G7: 118.9034 | H7: 119.9206 | I7: да | J7: -1.21783 | K7: =IF(J7>0,"прибыль",IF(J7<0,"убыток","ноль")) -> убыток | L7: =IF(C7="",L6,IF(J7<0,L6+1,0)) -> 1 | M7: -121.78 | N7: -8124.4 | O7: 12208.68
A8: 3 | B8: IS | C8: 2012-04-11 | D8: 2012-04-13 | E8: short | F8: 7371.73 | G8: 119.9206 | H8: 121.603 | J8: -1.69423 | K8: =IF(J8>0,"прибыль",IF(J8<0,"убыток","ноль")) -> убыток | L8: =IF(C8="",L7,IF(J8<0,L7+1,0)) -> 2 | M8: -169.42 | N8: -12489.4 | O8: -280.72
A9: 4 | B9: IS | C9: 2012-04-13 | D9: 2012-04-17 | E9: long | F9: 7198.1 | G9: 121.603 | H9: 118.2295 | I9: да | J9: 0.05967 | K9: =IF(J9>0,"прибыль",IF(J9<0,"убыток","ноль")) -> прибыль | L9: =IF(C9="",L8,IF(J9<0,L8+1,0)) -> 0 | M9: 5.97 | N9: 429.53 | O9: 148.82
A10: 5 | B10: IS | C10: 2012-04-17 | D10: 2012-04-18 | E10: short | F10: 7174.68 | G10: 118.2295 | H10: 118.8499 | J10: -0.6323 | K10: =IF(J10>0,"прибыль",IF(J10<0,"убыток","ноль")) -> убыток | L10: =IF(C10="",L9,IF(J10<0,L9+1,0)) -> 1 | M10: -63.23 | N10: -4536.55 | O10: -4387.74
A11: 6 | B11: IS | C11: 2012-04-18 | D11: 2012-04-19 | E11: long | F11: 7261.7 | G11: 118.8499 | H11: 118.0004 | J11: -0.86122 | K11: =IF(J11>0,"прибыль",IF(J11<0,"убыток","ноль")) -> убыток | L11: =IF(C11="",L10,IF(J11<0,L10+1,0)) -> 2 | M11: -86.12 | N11: -6253.92 | O11: -10641.66
A12: 7 | B12: IS | C12: 2012-04-19 | D12: 2012-06-05 | E12: short | F12: 1948.43 | G12: 118.2252 | H12: 99.2944 | I12: да | J12: 13.79115 | K12: =IF(J12>0,"прибыль",IF(J12<0,"убыток","ноль")) -> прибыль | L12: =IF(C12="",L11,IF(J12<0,L11+1,0)) -> 0 | M12: 1379.12 | N12: 26871.16 | O12: 16229.5
A13: 8 | B13: IS | C13: 2012-06-05 | D13: 2012-06-25 | E13: short | F13: 1554.51 | G13: 113.0951 | H13: 90.9197 | I13: да | J13: 23.12782 | K13: =IF(J13>0,"прибыль",IF(J13<0,"убыток","ноль")) -> прибыль | L13: =IF(C13="",L12,IF(J13<0,L12+1,0)) -> 0 | M13: 2312.78 | N13: 35952.48 | O13: 52181.98
A14: 9 | B14: IS | C14: 2012-06-25 | D14: 2012-07-02 | E14: short | F14: 1465.1 | G14: 114.0521 | H14: 97.171 | J14: 16.87617 | K14: =IF(J14>0,"прибыль",IF(J14<0,"убыток","ноль")) -> прибыль | L14: =IF(C14="",L13,IF(J14<0,L13+1,0)) -> 0 | M14: 1687.62 | N14: 24725.19 | O14: 76907.17
A15: 10 | B15: IS | C15: 2012-07-02 | D15: 2012-07-20 | E15: short | F15: 4144.45 | G15: 114.0521 | H15: 107.6325 | I15: да | J15: 6.43066 | K15: =IF(J15>0,"прибыль",IF(J15<0,"убыток","ноль")) -> прибыль | L15: =IF(C15="",L14,IF(J15<0,L14+1,0)) -> 0 | M15: 643.07 | N15: 26651.54 | O15: 103558.71
A16: 11 | B16: IS | C16: 2012-07-20 | D16: 2012-07-23 | E16: long | F16: 4226.27 | G16: 107.6325 | H16: 106.2087 | J16: -1.43448 | K16: =IF(J16>0,"прибыль",IF(J16<0,"убыток","ноль")) -> убыток | L16: =IF(C16="",L15,IF(J16<0,L15+1,0)) -> 1 | M16: -143.45 | N16: -6062.49 | O16: 97496.22
A17: 12 | B17: IS | C17: 2012-07-23 | D17: 2012-07-27 | E17: short | F17: 4253.01 | G17: 106.2087 | H17: 105.9135 | J17: 0.28476 | K17: =IF(J17>0,"прибыль",IF(J17<0,"убыток","ноль")) -> прибыль | L17: =IF(C17="",L16,IF(J17<0,L16+1,0)) -> 0 | M17: 28.48 | N17: 1211.1 | O17: 98707.33
A18: 13 | B18: IS | C18: 2012-07-27 | D18: 2012-09-20 | E18: long | F18: 3465.61 | G18: 110.6382 | H18: 107.7963 | I18: да | J18: -0.02838 | K18: =IF(J18>0,"прибыль",IF(J18<0,"убыток","ноль")) -> убыток | L18: =IF(C18="",L17,IF(J18<0,L17+1,0)) -> 1 | M18: -2.84 | N18: -98.37 | O18: 98608.96
A19: 14 | B19: IS | C19: 2012-09-20 | D19: 2012-09-28 | E19: long | F19: 1514.88 | G19: 107.8103 | H19: 112.2918 | J19: 4.47597 | K19: =IF(J19>0,"прибыль",IF(J19<0,"убыток","ноль")) -> прибыль | L19: =IF(C19="",L18,IF(J19<0,L18+1,0)) -> 0 | M19: 447.6 | N19: 6780.55 | O19: 105389.51
A20: 15 | B20: IS | C20: 2012-09-28 | D20: 2012-10-04 | E20: long | F20: 4936.86 | G20: 107.8103 | H20: 108.0738 | J20: 0.25272 | K20: =IF(J20>0,"прибыль",IF(J20<0,"убыток","ноль")) -> прибыль | L20: =IF(C20="",L19,IF(J20<0,L19+1,0)) -> 0 | M20: 25.27 | N20: 1247.63 | O20: 106637.14
A21: 16 | B21: IS | C21: 2012-10-04 | D21: 2012-10-05 | E21: short | F21: 4984.62 | G21: 108.0738 | H21: 112.4332 | J21: -4.36981 | K21: =IF(J21>0,"прибыль",IF(J21<0,"убыток","ноль")) -> убыток | L21: =IF(C21="",L20,IF(J21<0,L20+1,0)) -> 1 | M21: -436.98 | N21: -21781.83 | O21: 84855.31
A22: 17 | B22: IS | C22: 2012-10-05 | D22: 2012-10-18 | E22: long | F22: 4311.79 | G22: 112.4332 | H22: 113.3611 | I22: да | J22: 2.4113 | K22: =IF(J22>0,"прибыль",IF(J22<0,"убыток","ноль")) -> прибыль | L22: =IF(C22="",L21,IF(J22<0,L21+1,0)) -> 0 | M22: 241.13 | N22: 10397.04 | O22: 95252.35
A23: 18 | B23: IS | C23: 2012-10-18 | D23: 2012-10-22 | E23: short | F23: 4913.42 | G23: 113.3611 | H23: 110.8164 | J23: 2.53356 | K23: =IF(J23>0,"прибыль",IF(J23<0,"убыток","ноль")) -> прибыль | L23: =IF(C23="",L22,IF(J23<0,L22+1,0)) -> 0 | M23: 253.36 | N23: 12448.48 | O23: 107700.83
A24: 19 | B24: IS | C24: 2012-10-22 | D24: 2012-10-23 | E24: long | F24: 4926.58 | G24: 110.8164 | H24: 109.3241 | J24: -1.5033 | K24: =IF(J24>0,"прибыль",IF(J24<0,"убыток","ноль")) -> убыток | L24: =IF(C24="",L23,IF(J24<0,L23+1,0)) -> 1 | M24: -150.33 | N24: -7406.13 | O24: 100294.7
A25: 20 | B25: IS | C25: 2012-10-23 | D25: 2012-11-07 | E25: short | F25: 3025.61 | G25: 108.8544 | H25: 110.8192 | J25: -1.97664 | K25: =IF(J25>0,"прибыль",IF(J25<0,"убыток","ноль")) -> убыток | L25: =IF(C25="",L24,IF(J25<0,L24+1,0)) -> 2 | M25: -197.66 | N25: -5980.54 | O25: 94314.16
A26: 21 | B26: IS | C26: 2012-11-07 | D26: 2012-11-16 | E26: short | F26: 5411.97 | G26: 108.8544 | H26: 111.0845 | J26: -2.24043 | K26: =IF(J26>0,"прибыль",IF(J26<0,"убыток","ноль")) -> убыток | L26: =IF(C26="",L25,IF(J26<0,L25+1,0)) -> 3 | M26: -224.04 | N26: -12125.16 | O26: 82189
A27: 22 | B27: IS | C27: 2012-11-16 | D27: 2012-12-06 | E27: long | F27: 6637.4 | G27: 111.3173 | H27: 108.7609 | I27: да | J27: -0.80264 | K27: =IF(J27>0,"прибыль",IF(J27<0,"убыток","ноль")) -> убыток | L27: =IF(C27="",L26,IF(J27<0,L26+1,0)) -> 4 | M27: -80.26 | N27: -5327.42 | O27: 76861.58
A28: 23 | B28: IS | C28: 2012-12-06 | D28: 2012-12-19 | E28: short | F28: 10112.56 | G28: 108.6456 | H28: 108.9756 | I28: да | J28: -1.45746 | K28: =IF(J28>0,"прибыль",IF(J28<0,"убыток","ноль")) -> убыток | L28: =IF(C28="",L27,IF(J28<0,L27+1,0)) -> 5 | M28: -145.75 | N28: -14738.6 | O28: 62122.98
A29: 24 | B29: IS | C29: 2012-12-19 | D29: 2013-01-15 | E29: long | F29: 2505.04 | G29: 108.9756 | H29: 111.6208 | J29: 2.63959 | K29: =IF(J29>0,"прибыль",IF(J29<0,"убыток","ноль")) -> прибыль | L29: =IF(C29="",L28,IF(J29<0,L28+1,0)) -> 0 | M29: 263.96 | N29: 6612.29 | O29: 68735.28
A30: 25 | B30: IS | C30: 2013-01-15 | D30: 2013-02-21 | E30: long | F30: 3436.81 | G30: 113.0315 | H30: 115.1254 | I30: да | J30: 2.17271 | K30: =IF(J30>0,"прибыль",IF(J30<0,"убыток","ноль")) -> прибыль | L30: =IF(C30="",L29,IF(J30<0,L29+1,0)) -> 0 | M30: 217.27 | N30: 7467.17 | O30: 76202.45
A31: 26 | B31: IS | C31: 2013-02-21 | D31: 2013-03-04 | E31: long | F31: 11643.55 | G31: 112.9354 | H31: 110.2737 | J31: -2.67238 | K31: =IF(J31>0,"прибыль",IF(J31<0,"убыток","ноль")) -> убыток | L31: =IF(C31="",L30,IF(J31<0,L30+1,0)) -> 1 | M31: -267.24 | N31: -31116.05 | O31: 45086.4
A32: 27 | B32: IS | C32: 2013-03-04 | D32: 2013-04-04 | E32: short | F32: 3548.5 | G32: 109.5798 | H32: 107.3781 | I32: да | J32: 2.66261 | K32: =IF(J32>0,"прибыль",IF(J32<0,"убыток","ноль")) -> прибыль | L32: =IF(C32="",L31,IF(J32<0,L31+1,0)) -> 0 | M32: 266.26 | N32: 9448.28 | O32: 54534.68
A33: 28 | B33: IS | C33: 2013-04-04 | D33: 2013-04-16 | E33: short | F33: 2188.67 | G33: 110.0506 | H33: 100.3583 | J33: 9.68735 | K33: =IF(J33>0,"прибыль",IF(J33<0,"убыток","ноль")) -> прибыль | L33: =IF(C33="",L32,IF(J33<0,L32+1,0)) -> 0 | M33: 968.73 | N33: 21202.4 | O33: 75737.09
A34: 29 | B34: IS | C34: 2013-04-16 | D34: 2013-06-13 | E34: short | F34: 2106.04 | G34: 108.594 | H34: 103.2269 | I34: да | J34: 5.91615 | K34: =IF(J34>0,"прибыль",IF(J34<0,"убыток","ноль")) -> прибыль | L34: =IF(C34="",L33,IF(J34<0,L33+1,0)) -> 0 | M34: 591.62 | N34: 12459.63 | O34: 88196.71
A35: 30 | B35: IS | C35: 2013-06-13 | D35: 2013-06-14 | E35: short | F35: 8352.22 | G35: 109.1545 | H35: 104.2368 | J35: 4.90719 | K35: =IF(J35>0,"прибыль",IF(J35<0,"убыток","ноль")) -> прибыль | L35: =IF(C35="",L34,IF(J35<0,L34+1,0)) -> 0 | M35: 490.72 | N35: 40985.9 | O35: 129182.61
A36: 31 | B36: IS | C36: 2013-06-14 | D36: 2013-06-21 | E36: long | F36: 8340.51 | G36: 104.2368 | H36: 102.3762 | I36: да | J36: -3.23927 | K36: =IF(J36>0,"прибыль",IF(J36<0,"убыток","ноль")) -> убыток | L36: =IF(C36="",L35,IF(J36<0,L35+1,0)) -> 1 | M36: -323.93 | N36: -27017.14 | O36: 102165.47
A37: 32 | B37: IS | C37: 2013-06-21 | D37: 2013-07-08 | E37: short | F37: 7383.16 | G37: 102.3762 | H37: 107.7647 | J37: -5.39933 | K37: =IF(J37>0,"прибыль",IF(J37<0,"убыток","ноль")) -> убыток | L37: =IF(C37="",L36,IF(J37<0,L36+1,0)) -> 2 | M37: -539.93 | N37: -39864.13 | O37: 62301.34
A38: 33 | B38: IS | C38: 2013-07-08 | D38: 2013-08-28 | E38: long | F38: 4998.49 | G38: 108.5224 | H38: 114.261 | I38: да | J38: 7.34525 | K38: =IF(J38>0,"прибыль",IF(J38<0,"убыток","ноль")) -> прибыль | L38: =IF(C38="",L37,IF(J38<0,L37+1,0)) -> 0 | M38: 734.53 | N38: 36715.18 | O38: 99016.52
A39: 34 | B39: IS | C39: 2013-08-28 | D39: 2013-09-18 | E39: long | F39: 1763.73 | G39: 106.9037 | H39: 107.7106 | I39: да | J39: 3.12651 | K39: =IF(J39>0,"прибыль",IF(J39<0,"убыток","ноль")) -> прибыль | L39: =IF(C39="",L38,IF(J39<0,L38+1,0)) -> 0 | M39: 312.65 | N39: 5514.3 | O39: 104530.82
A40: 35 | B40: IS | C40: 2013-09-18 | D40: 2013-10-25 | E40: long | F40: 9306.95 | G40: 106.3233 | H40: 106.9235 | I40: да | J40: 2.46659 | K40: =IF(J40>0,"прибыль",IF(J40<0,"убыток","ноль")) -> прибыль | L40: =IF(C40="",L39,IF(J40<0,L39+1,0)) -> 0 | M40: 246.66 | N40: 22956.42 | O40: 127487.24
A41: 36 | B41: IS | C41: 2013-10-25 | D41: 2013-10-31 | E41: short | F41: 8580.23 | G41: 106.9235 | H41: 109.959 | J41: -3.04635 | K41: =IF(J41>0,"прибыль",IF(J41<0,"убыток","ноль")) -> убыток | L41: =IF(C41="",L40,IF(J41<0,L40+1,0)) -> 1 | M41: -304.64 | N41: -26138.39 | O41: 101348.86
...

Sheet 7F_1_TSMOM_NG
A1: 1 Time-Series Momentum · NG · lookback=90
A2: Параметры: лучший Шарп в выборке. Издержки ~7 б.п. за оборот вычтены.
A3: Каждая строка — исход по порядку закрытия. Пункт — единица котировки (BR: 1 USD за баррель, NG: 1 USD за MMBtu); плюс — прибыль, минус — убыток.
A5: № | B5: период | C5: вход | D5: выход | E5: направление | F5: объём, ед. актива | G5: цена входа | H5: цена выхода | I5: через ролл | J5: результат, пунктов | K5: исход | L5: серия убыточных подряд | M5: результат, шагов цены | N5: результат, USD | O5: итог, USD | P5: примечание
A6: 1 | B6: IS | C6: 2020-06-16 | D6: 2020-06-30 | E6: short | F6: 44555.81 | G6: 1.6668 | H6: 1.7117 | I6: да | J6: 0.0413 | K6: =IF(J6>0,"прибыль",IF(J6<0,"убыток","ноль")) -> прибыль | L6: =IF(AND(C6<>"",J6<0),1,0) -> 0 | M6: 41.3 | N6: 1840.33 | O6: 1840.33
A7: 2 | B7: IS | C7: 2020-06-30 | D7: 2020-08-04 | E7: short | F7: 137869.39 | G7: 1.7534 | H7: 2.1054 | I7: да | J7: -0.2508 | K7: =IF(J7>0,"прибыль",IF(J7<0,"убыток","ноль")) -> убыток | L7: =IF(C7="",L6,IF(J7<0,L6+1,0)) -> 1 | M7: -250.8 | N7: -34578.25 | O7: -32737.92
A8: 3 | B8: IS | C8: 2020-08-04 | D8: 2020-09-03 | E8: long | F8: 121044.81 | G8: 2.1877 | H8: 2.4975 | I8: да | J8: 0.08912 | K8: =IF(J8>0,"прибыль",IF(J8<0,"убыток","ноль")) -> прибыль | L8: =IF(C8="",L7,IF(J8<0,L7+1,0)) -> 0 | M8: 89.12 | N8: 10787.62 | O8: -21950.3
A9: 4 | B9: IS | C9: 2020-09-03 | D9: 2020-09-04 | E9: short | F9: 123238.84 | G9: 2.4975 | H9: 2.4824 | J9: 0.01491 | K9: =IF(J9>0,"прибыль",IF(J9<0,"убыток","ноль")) -> прибыль | L9: =IF(C9="",L8,IF(J9<0,L8+1,0)) -> 0 | M9: 14.91 | N9: 1837.04 | O9: -20113.25
A10: 5 | B10: IS | C10: 2020-09-04 | D10: 2020-09-09 | E10: long | F10: 126497.72 | G10: 2.4824 | H10: 2.3535 | J10: -0.12907 | K10: =IF(J10>0,"прибыль",IF(J10<0,"убыток","ноль")) -> убыток | L10: =IF(C10="",L9,IF(J10<0,L9+1,0)) -> 1 | M10: -129.07 | N10: -16327.38 | O10: -36440.64
A11: 6 | B11: IS | C11: 2020-09-09 | D11: 2020-09-10 | E11: short | F11: 121122.88 | G11: 2.3535 | H11: 2.4016 | J11: -0.04829 | K11: =IF(J11>0,"прибыль",IF(J11<0,"убыток","ноль")) -> убыток | L11: =IF(C11="",L10,IF(J11<0,L10+1,0)) -> 2 | M11: -48.29 | N11: -5849.55 | O11: -42290.18
A12: 7 | B12: IS | C12: 2020-09-10 | D12: 2020-09-11 | E12: long | F12: 118755.88 | G12: 2.4016 | H12: 2.3075 | J12: -0.0943 | K12: =IF(J12>0,"прибыль",IF(J12<0,"убыток","ноль")) -> убыток | L12: =IF(C12="",L11,IF(J12<0,L11+1,0)) -> 3 | M12: -94.3 | N12: -11198.3 | O12: -53488.48
A13: 8 | B13: IS | C13: 2020-09-11 | D13: 2020-09-14 | E13: short | F13: 0 | G13: 2.3075 | H13: 2.324 | J13: -0.01662 | K13: =IF(J13>0,"прибыль",IF(J13<0,"убыток","ноль")) -> убыток | L13: =IF(C13="",L12,IF(J13<0,L12+1,0)) -> 4 | M13: -16.62 | N13: 0 | O13: -53488.48
A14: 9 | B14: IS | C14: 2020-09-14 | D14: 2020-09-24 | E14: short | F14: 120797.98 | G14: 2.3075 | H14: 2.2064 | J14: 0.10095 | K14: =IF(J14>0,"прибыль",IF(J14<0,"убыток","ноль")) -> прибыль | L14: =IF(C14="",L13,IF(J14<0,L13+1,0)) -> 0 | M14: 100.95 | N14: 12194.17 | O14: -41294.31
A15: 10 | B15: IS | C15: 2020-09-24 | D15: 2020-09-25 | E15: long | F15: 68188.37 | G15: 2.2064 | H15: 2.1926 | J15: -0.014 | K15: =IF(J15>0,"прибыль",IF(J15<0,"убыток","ноль")) -> убыток | L15: =IF(C15="",L14,IF(J15<0,L14+1,0)) -> 1 | M15: -14 | N15: -954.78 | O15: -42249.09
A16: 11 | B16: IS | C16: 2020-09-25 | D16: 2020-09-28 | E16: short | F16: 0 | G16: 2.1926 | H16: 2.1452 | J16: 0.04731 | K16: =IF(J16>0,"прибыль",IF(J16<0,"убыток","ноль")) -> прибыль | L16: =IF(C16="",L15,IF(J16<0,L15+1,0)) -> 0 | M16: 47.31 | N16: 0 | O16: -42249.09
A17: 12 | B17: IS | C17: 2020-09-28 | D17: 2020-10-21 | E17: short | F17: 52905.68 | G17: 2.1926 | H17: 2.9204 | I17: да | J17: -0.08202 | K17: =IF(J17>0,"прибыль",IF(J17<0,"убыток","ноль")) -> убыток | L17: =IF(C17="",L16,IF(J17<0,L16+1,0)) -> 1 | M17: -82.02 | N17: -4339.35 | O17: -46588.44
A18: 13 | B18: IS | C18: 2020-10-21 | D18: 2020-11-10 | E18: long | F18: 79464.74 | G18: 2.9642 | H18: 2.8935 | I18: да | J18: -0.33618 | K18: =IF(J18>0,"прибыль",IF(J18<0,"убыток","ноль")) -> убыток | L18: =IF(C18="",L17,IF(J18<0,L17+1,0)) -> 2 | M18: -336.18 | N18: -26714.12 | O18: -73302.56
A19: 14 | B19: IS | C19: 2020-11-10 | D19: 2020-11-16 | E19: short | F19: 99387.62 | G19: 2.8935 | H19: 2.9865 | J19: -0.09333 | K19: =IF(J19>0,"прибыль",IF(J19<0,"убыток","ноль")) -> убыток | L19: =IF(C19="",L18,IF(J19<0,L18+1,0)) -> 3 | M19: -93.33 | N19: -9276.32 | O19: -82578.88
A20: 15 | B20: IS | C20: 2020-11-16 | D20: 2020-11-17 | E20: long | F20: 99541.6 | G20: 2.9865 | H20: 2.6841 | J20: -0.30263 | K20: =IF(J20>0,"прибыль",IF(J20<0,"убыток","ноль")) -> убыток | L20: =IF(C20="",L19,IF(J20<0,L19+1,0)) -> 4 | M20: -302.63 | N20: -30124.48 | O20: -112703.36
A21: 16 | B21: IS | C21: 2020-11-17 | D21: 2020-11-25 | E21: short | F21: 90661.42 | G21: 2.6841 | H21: 2.7796 | J21: -0.09575 | K21: =IF(J21>0,"прибыль",IF(J21<0,"убыток","ноль")) -> убыток | L21: =IF(C21="",L20,IF(J21<0,L20+1,0)) -> 5 | M21: -95.75 | N21: -8680.82 | O21: -121384.17
A22: 17 | B22: IS | C22: 2020-11-25 | D22: 2020-11-27 | E22: long | F22: 90936.71 | G22: 2.7796 | H22: 2.9181 | I22: да | J22: -0.0331 | K22: =IF(J22>0,"прибыль",IF(J22<0,"убыток","ноль")) -> убыток | L22: =IF(C22="",L21,IF(J22<0,L21+1,0)) -> 6 | M22: -33.1 | N22: -3010.29 | O22: -124394.47
A23: 18 | B23: IS | C23: 2020-11-27 | D23: 2021-02-05 | E23: short | F23: 24337.48 | G23: 2.8409 | H23: 2.9746 | I23: да | J23: 0.0751 | K23: =IF(J23>0,"прибыль",IF(J23<0,"убыток","ноль")) -> прибыль | L23: =IF(C23="",L22,IF(J23<0,L22+1,0)) -> 0 | M23: 75.1 | N23: 1827.86 | O23: -122566.61
A24: 19 | B24: IS | C24: 2021-02-05 | D24: 2021-04-19 | E24: short | F24: 167390.23 | G24: 2.8431 | H24: 2.6892 | I24: да | J24: 0.17073 | K24: =IF(J24>0,"прибыль",IF(J24<0,"убыток","ноль")) -> прибыль | L24: =IF(C24="",L23,IF(J24<0,L23+1,0)) -> 0 | M24: 170.73 | N24: 28579.27 | O24: -93987.35
A25: 20 | B25: IS | C25: 2021-04-19 | D25: 2021-04-22 | E25: long | F25: 195427.32 | G25: 2.6892 | H25: 2.6949 | J25: 0.00546 | K25: =IF(J25>0,"прибыль",IF(J25<0,"убыток","ноль")) -> прибыль | L25: =IF(C25="",L24,IF(J25<0,L24+1,0)) -> 0 | M25: 5.46 | N25: 1066.55 | O25: -92920.8
A26: 21 | B26: IS | C26: 2021-04-22 | D26: 2021-04-23 | E26: short | F26: 0 | G26: 2.6949 | H26: 2.7542 | J26: -0.05941 | K26: =IF(J26>0,"прибыль",IF(J26<0,"убыток","ноль")) -> убыток | L26: =IF(C26="",L25,IF(J26<0,L25+1,0)) -> 1 | M26: -59.41 | N26: 0 | O26: -92920.8
A27: 22 | B27: IS | C27: 2021-04-23 | D27: 2021-05-06 | E27: short | F27: 194124.39 | G27: 2.6949 | H27: 2.953 | I27: да | J27: -0.18708 | K27: =IF(J27>0,"прибыль",IF(J27<0,"убыток","ноль")) -> убыток | L27: =IF(C27="",L26,IF(J27<0,L26+1,0)) -> 2 | M27: -187.08 | N27: -36316.69 | O27: -129237.49
A28: 23 | B28: IS | C28: 2021-05-06 | D28: 2021-05-18 | E28: long | F28: 50040.34 | G28: 2.953 | H28: 3.1164 | J28: 0.16327 | K28: =IF(J28>0,"прибыль",IF(J28<0,"убыток","ноль")) -> прибыль | L28: =IF(C28="",L27,IF(J28<0,L27+1,0)) -> 0 | M28: 163.27 | N28: 8169.94 | O28: -121067.55
A29: 24 | B29: IS | C29: 2021-05-18 | D29: 2021-07-07 | E29: long | F29: 37519.98 | G29: 2.953 | H29: 3.6742 | I29: да | J29: 0.54462 | K29: =IF(J29>0,"прибыль",IF(J29<0,"убыток","ноль")) -> прибыль | L29: =IF(C29="",L28,IF(J29<0,L28+1,0)) -> 0 | M29: 544.62 | N29: 20434.03 | O29: -100633.52
A30: 25 | B30: IS | C30: 2021-07-07 | D30: 2021-08-27 | E30: long | F30: 35905.63 | G30: 3.1294 | H30: 4.1776 | I30: да | J30: 1.07401 | K30: =IF(J30>0,"прибыль",IF(J30<0,"убыток","ноль")) -> прибыль | L30: =IF(C30="",L29,IF(J30<0,L29+1,0)) -> 0 | M30: 1074.01 | N30: 38563.04 | O30: -62070.47
A31: 26 | B31: IS | C31: 2021-08-27 | D31: 2021-09-09 | E31: long | F31: 21144.41 | G31: 3.1034 | H31: 4.9153 | I31: да | J31: 1.64779 | K31: =IF(J31>0,"прибыль",IF(J31<0,"убыток","ноль")) -> прибыль | L31: =IF(C31="",L30,IF(J31<0,L30+1,0)) -> 0 | M31: 1647.79 | N31: 34841.57 | O31: -27228.9
A32: 27 | B32: IS | C32: 2021-09-09 | D32: 2021-09-28 | E32: long | F32: 19974.59 | G32: 3.2673 | H32: 5.6948 | J32: 2.42725 | K32: =IF(J32>0,"прибыль",IF(J32<0,"убыток","ноль")) -> прибыль | L32: =IF(C32="",L31,IF(J32<0,L31+1,0)) -> 0 | M32: 2427.25 | N32: 48483.41 | O32: 21254.5
A33: 28 | B33: IS | C33: 2021-09-28 | D33: 2021-10-05 | E33: long | F33: 9538.47 | G33: 3.2673 | H33: 5.8046 | I33: да | J33: 2.47629 | K33: =IF(J33>0,"прибыль",IF(J33<0,"убыток","ноль")) -> прибыль | L33: =IF(C33="",L32,IF(J33<0,L32+1,0)) -> 0 | M33: 2476.29 | N33: 23620 | O33: 44874.51
A34: 29 | B34: IS | C34: 2021-10-05 | D34: 2021-10-26 | E34: long | F34: 6815.96 | G34: 3.328 | H34: 5.9809 | J34: 2.65267 | K34: =IF(J34>0,"прибыль",IF(J34<0,"убыток","ноль")) -> прибыль | L34: =IF(C34="",L33,IF(J34<0,L33+1,0)) -> 0 | M34: 2652.67 | N34: 18080.47 | O34: 62954.97
A35: 30 | B35: IS | C35: 2021-10-26 | D35: 2021-12-01 | E35: long | F35: 35354.14 | G35: 3.8889 | H35: 4.5909 | I35: да | J35: 0.26611 | K35: =IF(J35>0,"прибыль",IF(J35<0,"убыток","ноль")) -> прибыль | L35: =IF(C35="",L34,IF(J35<0,L34+1,0)) -> 0 | M35: 266.11 | N35: 9407.96 | O35: 72362.93
A36: 31 | B36: IS | C36: 2021-12-01 | D36: 2022-01-13 | E36: short | F36: 19965.43 | G36: 4.3887 | H36: 4.8299 | I36: да | J36: -0.6614 | K36: =IF(J36>0,"прибыль",IF(J36<0,"убыток","ноль")) -> убыток | L36: =IF(C36="",L35,IF(J36<0,L35+1,0)) -> 1 | M36: -661.4 | N36: -13205.2 | O36: 59157.73
A37: 32 | B37: IS | C37: 2022-01-13 | D37: 2022-02-03 | E37: short | F37: 9129.15 | G37: 4.1689 | H37: 5.4498 | I37: да | J37: -1.20222 | K37: =IF(J37>0,"прибыль",IF(J37<0,"убыток","ноль")) -> убыток | L37: =IF(C37="",L36,IF(J37<0,L36+1,0)) -> 2 | M37: -1202.22 | N37: -10975.22 | O37: 48182.51
A38: 33 | B38: IS | C38: 2022-02-03 | D38: 2022-03-28 | E38: short | F38: 48339.55 | G38: 4.2727 | H38: 5.3505 | I38: да | J38: -1.00818 | K38: =IF(J38>0,"прибыль",IF(J38<0,"убыток","ноль")) -> убыток | L38: =IF(C38="",L37,IF(J38<0,L37+1,0)) -> 3 | M38: -1008.18 | N38: -48734.83 | O38: -552.33
A39: 34 | B39: IS | C39: 2022-03-28 | D39: 2022-04-19 | E39: long | F39: 16837.67 | G39: 5.5184 | H39: 7.1895 | I39: да | J39: 2.00814 | K39: =IF(J39>0,"прибыль",IF(J39<0,"убыток","ноль")) -> прибыль | L39: =IF(C39="",L38,IF(J39<0,L38+1,0)) -> 0 | M39: 2008.14 | N39: 33812.4 | O39: 33260.07
A40: 35 | B40: IS | C40: 2022-04-19 | D40: 2022-04-27 | E40: long | F40: 14484.62 | G40: 5.1807 | H40: 6.8356 | J40: 1.65456 | K40: =IF(J40>0,"прибыль",IF(J40<0,"убыток","ноль")) -> прибыль | L40: =IF(C40="",L39,IF(J40<0,L39+1,0)) -> 0 | M40: 1654.56 | N40: 23965.64 | O40: 57225.71
A41: 36 | B41: IS | C41: 2022-04-27 | D41: 2022-05-05 | E41: long | F41: 10194.65 | G41: 5.1807 | H41: 7.6313 | I41: да | J41: 2.26116 | K41: =IF(J41>0,"прибыль",IF(J41<0,"убыток","ноль")) -> прибыль | L41: =IF(C41="",L40,IF(J41<0,L40+1,0)) -> 0 | M41: 2261.16 | N41: 23051.78 | O41: 80277.49
...

Sheet 7F_2_DualMA_BR
A1: 2 Dual Moving Average · BR · fast=20,slow=60
A2: Параметры: лучший Шарп в выборке. Издержки ~7 б.п. за оборот вычтены.
A3: Каждая строка — исход по порядку закрытия. Пункт — единица котировки (BR: 1 USD за баррель, NG: 1 USD за MMBtu); плюс — прибыль, минус — убыток.
A5: № | B5: период | C5: вход | D5: выход | E5: направление | F5: объём, ед. актива | G5: цена входа | H5: цена выхода | I5: через ролл | J5: результат, пунктов | K5: исход | L5: серия убыточных подряд | M5: результат, шагов цены | N5: результат, USD | O5: итог, USD | P5: примечание
A6: 1 | B6: IS | C6: 2012-03-15 | D6: 2012-04-24 | E6: long | F6: 7841.95 | G6: 123.889 | H6: 118.5931 | I6: да | J6: -4.05397 | K6: =IF(J6>0,"прибыль",IF(J6<0,"убыток","ноль")) -> убыток | L6: =IF(AND(C6<>"",J6<0),1,0) -> 1 | M6: -405.4 | N6: -31791.02 | O6: -31791.02
A7: 2 | B7: IS | C7: 2012-04-24 | D7: 2012-06-04 | E7: short | F7: 2449.33 | G7: 117.4575 | H7: 96.9713 | I7: да | J7: 15.38046 | K7: =IF(J7>0,"прибыль",IF(J7<0,"убыток","ноль")) -> прибыль | L7: =IF(C7="",L6,IF(J7<0,L6+1,0)) -> 0 | M7: 1538.05 | N7: 37671.91 | O7: 5880.89
A8: 3 | B8: IS | C8: 2012-06-04 | D8: 2012-06-25 | E8: short | F8: 1692.35 | G8: 112.3607 | H8: 90.9197 | I8: да | J8: 22.38723 | K8: =IF(J8>0,"прибыль",IF(J8<0,"убыток","ноль")) -> прибыль | L8: =IF(C8="",L7,IF(J8<0,L7+1,0)) -> 0 | M8: 2238.72 | N8: 37886.99 | O8: 43767.88
A9: 4 | B9: IS | C9: 2012-06-25 | D9: 2012-07-02 | E9: short | F9: 1465.1 | G9: 113.3115 | H9: 97.171 | J9: 16.13558 | K9: =IF(J9>0,"прибыль",IF(J9<0,"убыток","ноль")) -> прибыль | L9: =IF(C9="",L8,IF(J9<0,L8+1,0)) -> 0 | M9: 1613.56 | N9: 23640.17 | O9: 67408.05
A10: 5 | B10: IS | C10: 2012-07-02 | D10: 2012-07-30 | E10: short | F10: 4144.45 | G10: 113.3115 | H10: 106.6737 | I10: да | J10: 6.6478 | K10: =IF(J10>0,"прибыль",IF(J10<0,"убыток","ноль")) -> прибыль | L10: =IF(C10="",L9,IF(J10<0,L9+1,0)) -> 0 | M10: 664.78 | N10: 27551.47 | O10: 94959.52
A11: 6 | B11: IS | C11: 2012-07-30 | D11: 2012-09-20 | E11: long | F11: 3465.61 | G11: 110.9674 | H11: 107.7963 | I11: да | J11: -0.34778 | K11: =IF(J11>0,"прибыль",IF(J11<0,"убыток","ноль")) -> убыток | L11: =IF(C11="",L10,IF(J11<0,L10+1,0)) -> 1 | M11: -34.78 | N11: -1205.26 | O11: 93754.26
A12: 7 | B12: IS | C12: 2012-09-20 | D12: 2012-09-28 | E12: long | F12: 1514.88 | G12: 108.131 | H12: 112.2918 | J12: 4.15518 | K12: =IF(J12>0,"прибыль",IF(J12<0,"убыток","ноль")) -> прибыль | L12: =IF(C12="",L11,IF(J12<0,L11+1,0)) -> 0 | M12: 415.52 | N12: 6294.61 | O12: 100048.87
A13: 8 | B13: IS | C13: 2012-09-28 | D13: 2012-10-29 | E13: long | F13: 5003.41 | G13: 108.131 | H13: 109.2428 | I13: да | J13: 2.53865 | K13: =IF(J13>0,"прибыль",IF(J13<0,"убыток","ноль")) -> прибыль | L13: =IF(C13="",L12,IF(J13<0,L12+1,0)) -> 0 | M13: 253.86 | N13: 12701.9 | O13: 112750.77
A14: 9 | B14: IS | C14: 2012-10-29 | D14: 2012-11-07 | E14: short | F14: 3025.61 | G14: 108.8396 | H14: 110.8192 | J14: -1.99031 | K14: =IF(J14>0,"прибыль",IF(J14<0,"убыток","ноль")) -> убыток | L14: =IF(C14="",L13,IF(J14<0,L13+1,0)) -> 1 | M14: -199.03 | N14: -6021.9 | O14: 106728.88
A15: 10 | B15: IS | C15: 2012-11-07 | D15: 2012-12-04 | E15: short | F15: 5499.29 | G15: 108.8396 | H15: 110.8732 | I15: да | J15: -3.77257 | K15: =IF(J15>0,"прибыль",IF(J15<0,"убыток","ноль")) -> убыток | L15: =IF(C15="",L14,IF(J15<0,L14+1,0)) -> 2 | M15: -377.26 | N15: -20746.5 | O15: 85982.38
A16: 11 | B16: IS | C16: 2012-12-04 | D16: 2013-01-16 | E16: long | F16: 2135.35 | G16: 109.9905 | H16: 110.4083 | I16: да | J16: 1.52891 | K16: =IF(J16>0,"прибыль",IF(J16<0,"убыток","ноль")) -> прибыль | L16: =IF(C16="",L15,IF(J16<0,L15+1,0)) -> 0 | M16: 152.89 | N16: 3264.76 | O16: 89247.14
A17: 12 | B17: IS | C17: 2013-01-16 | D17: 2013-02-21 | E17: long | F17: 3436.81 | G17: 112.7547 | H17: 115.1254 | I17: да | J17: 2.44872 | K17: =IF(J17>0,"прибыль",IF(J17<0,"убыток","ноль")) -> прибыль | L17: =IF(C17="",L16,IF(J17<0,L16+1,0)) -> 0 | M17: 244.87 | N17: 8415.79 | O17: 97662.93
A18: 13 | B18: IS | C18: 2013-02-21 | D18: 2013-03-19 | E18: long | F18: 11593.73 | G18: 112.6589 | H18: 109.2263 | I18: да | J18: -3.9275 | K18: =IF(J18>0,"прибыль",IF(J18<0,"убыток","ноль")) -> убыток | L18: =IF(C18="",L17,IF(J18<0,L17+1,0)) -> 1 | M18: -392.75 | N18: -45534.4 | O18: 52128.53
A19: 14 | B19: IS | C19: 2013-03-19 | D19: 2013-04-04 | E19: short | F19: 3548.5 | G19: 108.9412 | H19: 107.3781 | J19: 1.55416 | K19: =IF(J19>0,"прибыль",IF(J19<0,"убыток","ноль")) -> прибыль | L19: =IF(C19="",L18,IF(J19<0,L18+1,0)) -> 0 | M19: 155.42 | N19: 5514.93 | O19: 57643.46
A20: 15 | B20: IS | C20: 2013-04-04 | D20: 2013-04-16 | E20: short | F20: 2188.67 | G20: 108.9412 | H20: 100.3583 | J20: 8.5779 | K20: =IF(J20>0,"прибыль",IF(J20<0,"убыток","ноль")) -> прибыль | L20: =IF(C20="",L19,IF(J20<0,L19+1,0)) -> 0 | M20: 857.79 | N20: 18774.18 | O20: 76417.64
A21: 16 | B21: IS | C21: 2013-04-16 | D21: 2013-06-13 | E21: short | F21: 2106.04 | G21: 107.7515 | H21: 103.2269 | I21: да | J21: 5.06932 | K21: =IF(J21>0,"прибыль",IF(J21<0,"убыток","ноль")) -> прибыль | L21: =IF(C21="",L20,IF(J21<0,L20+1,0)) -> 0 | M21: 506.93 | N21: 10676.16 | O21: 87093.79
A22: 17 | B22: IS | C22: 2013-06-13 | D22: 2013-07-17 | E22: short | F22: 8243.94 | G22: 108.3077 | H22: 109.4921 | I22: да | J22: 0.22734 | K22: =IF(J22>0,"прибыль",IF(J22<0,"убыток","ноль")) -> прибыль | L22: =IF(C22="",L21,IF(J22<0,L21+1,0)) -> 0 | M22: 22.73 | N22: 1874.21 | O22: 88968.01
A23: 18 | B23: IS | C23: 2013-07-17 | D23: 2013-08-28 | E23: long | F23: 4998.49 | G23: 109.4956 | H23: 114.261 | I23: да | J23: 6.38691 | K23: =IF(J23>0,"прибыль",IF(J23<0,"убыток","ноль")) -> прибыль | L23: =IF(C23="",L22,IF(J23<0,L22+1,0)) -> 0 | M23: 638.69 | N23: 31924.93 | O23: 120892.93
A24: 19 | B24: IS | C24: 2013-08-28 | D24: 2013-09-18 | E24: long | F24: 1763.73 | G24: 107.8624 | H24: 107.7106 | I24: да | J24: 2.18867 | K24: =IF(J24>0,"прибыль",IF(J24<0,"убыток","ноль")) -> прибыль | L24: =IF(C24="",L23,IF(J24<0,L23+1,0)) -> 0 | M24: 218.87 | N24: 3860.21 | O24: 124753.14
A25: 20 | B25: IS | C25: 2013-09-18 | D25: 2013-11-12 | E25: long | F25: 9306.95 | G25: 107.0364 | H25: 106.2561 | I25: да | J25: 1.09939 | K25: =IF(J25>0,"прибыль",IF(J25<0,"убыток","ноль")) -> прибыль | L25: =IF(C25="",L24,IF(J25<0,L24+1,0)) -> 0 | M25: 109.94 | N25: 10231.92 | O25: 134985.07
A26: 21 | B26: IS | C26: 2013-11-12 | D26: 2013-11-13 | E26: short | F26: 0 | G26: 106.2561 | H26: 106.0435 | J26: 0.20731 | K26: =IF(J26>0,"прибыль",IF(J26<0,"убыток","ноль")) -> прибыль | L26: =IF(C26="",L25,IF(J26<0,L25+1,0)) -> 0 | M26: 20.73 | N26: 0 | O26: 134985.07
A27: 22 | B27: IS | C27: 2013-11-13 | D27: 2013-12-02 | E27: short | F27: 7545.94 | G27: 106.2561 | H27: 110.1445 | I27: да | J27: -4.17346 | K27: =IF(J27>0,"прибыль",IF(J27<0,"убыток","ноль")) -> убыток | L27: =IF(C27="",L26,IF(J27<0,L26+1,0)) -> 1 | M27: -417.35 | N27: -31492.7 | O27: 103492.37
A28: 23 | B28: IS | C28: 2013-12-02 | D28: 2014-02-03 | E28: long | F28: 9458.43 | G28: 110.4454 | H28: 106.2731 | I28: да | J28: -1.73778 | K28: =IF(J28>0,"прибыль",IF(J28<0,"убыток","ноль")) -> убыток | L28: =IF(C28="",L27,IF(J28<0,L27+1,0)) -> 2 | M28: -173.78 | N28: -16436.7 | O28: 87055.67
A29: 24 | B29: IS | C29: 2014-02-03 | D29: 2014-02-10 | E29: short | F29: 2756.74 | G29: 106.1485 | H29: 109.4568 | J29: -3.32316 | K29: =IF(J29>0,"прибыль",IF(J29<0,"убыток","ноль")) -> убыток | L29: =IF(C29="",L28,IF(J29<0,L28+1,0)) -> 3 | M29: -332.32 | N29: -9161.11 | O29: 77894.57
A30: 25 | B30: IS | C30: 2014-02-10 | D30: 2014-02-25 | E30: short | F30: 10570.66 | G30: 106.1485 | H30: 110.6244 | I30: да | J30: -4.16518 | K30: =IF(J30>0,"прибыль",IF(J30<0,"убыток","ноль")) -> убыток | L30: =IF(C30="",L29,IF(J30<0,L29+1,0)) -> 4 | M30: -416.52 | N30: -44028.67 | O30: 33865.89
A31: 26 | B31: IS | C31: 2014-02-25 | D31: 2014-04-29 | E31: long | F31: 2363.77 | G31: 110.6244 | H31: 108.4061 | I31: да | J31: -0.73836 | K31: =IF(J31>0,"прибыль",IF(J31<0,"убыток","ноль")) -> убыток | L31: =IF(C31="",L30,IF(J31<0,L30+1,0)) -> 5 | M31: -73.84 | N31: -1745.31 | O31: 32120.59
A32: 27 | B32: IS | C32: 2014-04-29 | D32: 2014-06-16 | E32: long | F32: 7532.51 | G32: 109.4862 | H32: 113.2917 | I32: да | J32: 4.35851 | K32: =IF(J32>0,"прибыль",IF(J32<0,"убыток","ноль")) -> прибыль | L32: =IF(C32="",L31,IF(J32<0,L31+1,0)) -> 0 | M32: 435.85 | N32: 32830.48 | O32: 64951.07
A33: 28 | B33: IS | C33: 2014-06-16 | D33: 2014-07-22 | E33: long | F33: 12954.64 | G33: 108.5301 | H33: 107.7835 | I33: да | J33: -2.62631 | K33: =IF(J33>0,"прибыль",IF(J33<0,"убыток","ноль")) -> убыток | L33: =IF(C33="",L32,IF(J33<0,L32+1,0)) -> 1 | M33: -262.63 | N33: -34022.92 | O33: 30928.15
A34: 29 | B34: IS | C34: 2014-07-22 | D34: 2014-08-15 | E34: short | F34: 2873.15 | G34: 107.7835 | H34: 102.3138 | J34: 5.46461 | K34: =IF(J34>0,"прибыль",IF(J34<0,"убыток","ноль")) -> прибыль | L34: =IF(C34="",L33,IF(J34<0,L33+1,0)) -> 0 | M34: 546.46 | N34: 15700.67 | O34: 46628.82
A35: 30 | B35: IS | C35: 2014-08-15 | D35: 2014-10-15 | E35: short | F35: 3642.92 | G35: 103.7109 | H35: 85.2819 | I35: да | J35: 22.32035 | K35: =IF(J35>0,"прибыль",IF(J35<0,"убыток","ноль")) -> прибыль | L35: =IF(C35="",L34,IF(J35<0,L34+1,0)) -> 0 | M35: 2232.04 | N35: 81311.29 | O35: 127940.12
A36: 31 | B36: IS | C36: 2014-10-15 | D36: 2014-10-30 | E36: short | F36: 2029.61 | G36: 107.6108 | H36: 87.1156 | I36: да | J36: 22.706 | K36: =IF(J36>0,"прибыль",IF(J36<0,"убыток","ноль")) -> прибыль | L36: =IF(C36="",L35,IF(J36<0,L35+1,0)) -> 0 | M36: 2270.6 | N36: 46084.22 | O36: 174024.34
A37: 32 | B37: IS | C37: 2014-10-30 | D37: 2014-11-28 | E37: short | F37: 2204.07 | G37: 102.7889 | H37: 72.5912 | I37: да | J37: 32.56965 | K37: =IF(J37>0,"прибыль",IF(J37<0,"убыток","ноль")) -> прибыль | L37: =IF(C37="",L36,IF(J37<0,L36+1,0)) -> 0 | M37: 3256.96 | N37: 71785.9 | O37: 245810.24
A38: 33 | B38: IS | C38: 2014-11-28 | D38: 2014-12-24 | E38: short | F38: 1744.32 | G38: 105.1689 | H38: 61.657 | I38: да | J38: 45.61922 | K38: =IF(J38>0,"прибыль",IF(J38<0,"убыток","ноль")) -> прибыль | L38: =IF(C38="",L37,IF(J38<0,L37+1,0)) -> 0 | M38: 4561.92 | N38: 79574.37 | O38: 325384.61
A39: 34 | B39: IS | C39: 2014-12-24 | D39: 2015-02-03 | E39: short | F39: 2114.7 | G39: 95.9603 | H39: 55.0057 | I39: да | J39: 45.51806 | K39: =IF(J39>0,"прибыль",IF(J39<0,"убыток","ноль")) -> прибыль | L39: =IF(C39="",L38,IF(J39<0,L38+1,0)) -> 0 | M39: 4551.81 | N39: 96257.25 | O39: 421641.86
A40: 35 | B40: IS | C40: 2015-02-03 | D40: 2015-03-16 | E40: short | F40: 5987 | G40: 92.3668 | H40: 54.5425 | I40: да | J40: 44.54454 | K40: =IF(J40>0,"прибыль",IF(J40<0,"убыток","ноль")) -> прибыль | L40: =IF(C40="",L39,IF(J40<0,L39+1,0)) -> 0 | M40: 4454.45 | N40: 266688.18 | O40: 688330.04
A41: 36 | B41: IS | C41: 2015-03-16 | D41: 2015-03-17 | E41: long | F41: 6110.35 | G41: 54.5425 | H41: 53.2035 | J41: -1.34454 | K41: =IF(J41>0,"прибыль",IF(J41<0,"убыток","ноль")) -> убыток | L41: =IF(C41="",L40,IF(J41<0,L40+1,0)) -> 1 | M41: -134.45 | N41: -8215.59 | O41: 680114.46
...

Sheet 7F_2_DualMA_NG
A1: 2 Dual Moving Average · NG · fast=20,slow=150
A2: Параметры: лучший Шарп в выборке. Издержки ~7 б.п. за оборот вычтены.
A3: Каждая строка — исход по порядку закрытия. Пункт — единица котировки (BR: 1 USD за баррель, NG: 1 USD за MMBtu); плюс — прибыль, минус — убыток.
A5: № | B5: период | C5: вход | D5: выход | E5: направление | F5: объём, ед. актива | G5: цена входа | H5: цена выхода | I5: через ролл | J5: результат, пунктов | K5: исход | L5: серия убыточных подряд | M5: результат, шагов цены | N5: результат, USD | O5: итог, USD | P5: примечание
A6: 1 | B6: IS | C6: 2020-09-09 | D6: 2020-09-24 | E6: long | F6: 52934.52 | G6: 2.3625 | H6: 2.1916 | J6: -0.17125 | K6: =IF(J6>0,"прибыль",IF(J6<0,"убыток","ноль")) -> убыток | L6: =IF(AND(C6<>"",J6<0),1,0) -> 1 | M6: -171.25 | N6: -9065.19 | O6: -9065.19
A7: 2 | B7: IS | C7: 2020-09-24 | D7: 2020-09-29 | E7: long | F7: 52668.62 | G7: 2.3625 | H7: 2.7587 | I7: да | J7: -0.30022 | K7: =IF(J7>0,"прибыль",IF(J7<0,"убыток","ноль")) -> убыток | L7: =IF(C7="",L6,IF(J7<0,L6+1,0)) -> 2 | M7: -300.22 | N7: -15812.25 | O7: -24877.44
A8: 3 | B8: IS | C8: 2020-09-29 | D8: 2021-02-05 | E8: short | F8: 24337.48 | G8: 2.7072 | H8: 2.9746 | I8: да | J8: 0.38633 | K8: =IF(J8>0,"прибыль",IF(J8<0,"убыток","ноль")) -> прибыль | L8: =IF(C8="",L7,IF(J8<0,L7+1,0)) -> 0 | M8: 386.33 | N8: 9402.24 | O8: -15475.2
A9: 4 | B9: IS | C9: 2021-02-05 | D9: 2021-05-19 | E9: short | F9: 52265.53 | G9: 2.967 | H9: 3.0068 | I9: да | J9: 0.05664 | K9: =IF(J9>0,"прибыль",IF(J9<0,"убыток","ноль")) -> прибыль | L9: =IF(C9="",L8,IF(J9<0,L8+1,0)) -> 0 | M9: 56.64 | N9: 2960.28 | O9: -12514.92
A10: 5 | B10: IS | C10: 2021-05-19 | D10: 2021-06-02 | E10: short | F10: 153353.78 | G10: 3.0639 | H10: 3.0957 | I10: да | J10: 0.07835 | K10: =IF(J10>0,"прибыль",IF(J10<0,"убыток","ноль")) -> прибыль | L10: =IF(C10="",L9,IF(J10<0,L9+1,0)) -> 0 | M10: 78.35 | N10: 12015.83 | O10: -499.09
A11: 6 | B11: IS | C11: 2021-06-02 | D11: 2021-07-07 | E11: long | F11: 37265.92 | G11: 3.0957 | H11: 3.6742 | I11: да | J11: 0.50749 | K11: =IF(J11>0,"прибыль",IF(J11<0,"убыток","ноль")) -> прибыль | L11: =IF(C11="",L10,IF(J11<0,L10+1,0)) -> 0 | M11: 507.49 | N11: 18912.19 | O11: 18413.1
A12: 7 | B12: IS | C12: 2021-07-07 | D12: 2021-08-27 | E12: long | F12: 35905.63 | G12: 3.1665 | H12: 4.1776 | I12: да | J12: 1.03719 | K12: =IF(J12>0,"прибыль",IF(J12<0,"убыток","ноль")) -> прибыль | L12: =IF(C12="",L11,IF(J12<0,L11+1,0)) -> 0 | M12: 1037.19 | N12: 37241.14 | O12: 55654.24
A13: 8 | B13: IS | C13: 2021-08-27 | D13: 2021-09-09 | E13: long | F13: 21144.41 | G13: 3.1402 | H13: 4.9153 | I13: да | J13: 1.60903 | K13: =IF(J13>0,"прибыль",IF(J13<0,"убыток","ноль")) -> прибыль | L13: =IF(C13="",L12,IF(J13<0,L12+1,0)) -> 0 | M13: 1609.03 | N13: 34022.01 | O13: 89676.25
A14: 9 | B14: IS | C14: 2021-09-09 | D14: 2021-09-28 | E14: long | F14: 19974.59 | G14: 3.306 | H14: 5.6948 | J14: 2.38849 | K14: =IF(J14>0,"прибыль",IF(J14<0,"убыток","ноль")) -> прибыль | L14: =IF(C14="",L13,IF(J14<0,L13+1,0)) -> 0 | M14: 2388.49 | N14: 47709.19 | O14: 137385.44
A15: 10 | B15: IS | C15: 2021-09-28 | D15: 2021-10-05 | E15: long | F15: 9538.47 | G15: 3.306 | H15: 5.8046 | I15: да | J15: 2.43681 | K15: =IF(J15>0,"прибыль",IF(J15<0,"убыток","ноль")) -> прибыль | L15: =IF(C15="",L14,IF(J15<0,L14+1,0)) -> 0 | M15: 2436.81 | N15: 23243.42 | O15: 160628.86
A16: 11 | B16: IS | C16: 2021-10-05 | D16: 2021-10-26 | E16: long | F16: 6815.96 | G16: 3.3675 | H16: 5.9809 | J16: 2.61319 | K16: =IF(J16>0,"прибыль",IF(J16<0,"убыток","ноль")) -> прибыль | L16: =IF(C16="",L15,IF(J16<0,L15+1,0)) -> 0 | M16: 2613.19 | N16: 17811.37 | O16: 178440.23
A17: 12 | B17: IS | C17: 2021-10-26 | D17: 2021-12-09 | E17: long | F17: 43228.55 | G17: 3.9017 | H17: 3.8056 | I17: да | J17: -0.53342 | K17: =IF(J17>0,"прибыль",IF(J17<0,"убыток","ноль")) -> убыток | L17: =IF(C17="",L16,IF(J17<0,L16+1,0)) -> 1 | M17: -533.42 | N17: -23058.88 | O17: 155381.35
A18: 13 | B18: IS | C18: 2021-12-09 | D18: 2022-01-13 | E18: short | F18: 26391.71 | G18: 3.7763 | H18: 4.8299 | I18: да | J18: -1.24305 | K18: =IF(J18>0,"прибыль",IF(J18<0,"убыток","ноль")) -> убыток | L18: =IF(C18="",L17,IF(J18<0,L17+1,0)) -> 2 | M18: -1243.05 | N18: -32806.1 | O18: 122575.24
A19: 14 | B19: IS | C19: 2022-01-13 | D19: 2022-02-03 | E19: short | F19: 9129.15 | G19: 3.5872 | H19: 5.4498 | I19: да | J19: -1.79496 | K19: =IF(J19>0,"прибыль",IF(J19<0,"убыток","ноль")) -> убыток | L19: =IF(C19="",L18,IF(J19<0,L18+1,0)) -> 3 | M19: -1794.96 | N19: -16386.46 | O19: 106188.79
A20: 15 | B20: IS | C20: 2022-02-03 | D20: 2022-04-01 | E20: short | F20: 51490.51 | G20: 3.9085 | H20: 5.4655 | I20: да | J20: -1.73654 | K20: =IF(J20>0,"прибыль",IF(J20<0,"убыток","ноль")) -> убыток | L20: =IF(C20="",L19,IF(J20<0,L19+1,0)) -> 4 | M20: -1736.54 | N20: -89415.09 | O20: 16773.7
A21: 16 | B21: IS | C21: 2022-04-01 | D21: 2022-04-19 | E21: long | F21: 16837.67 | G21: 5.5159 | H21: 7.1895 | J21: 1.67296 | K21: =IF(J21>0,"прибыль",IF(J21<0,"убыток","ноль")) -> прибыль | L21: =IF(C21="",L20,IF(J21<0,L20+1,0)) -> 0 | M21: 1672.96 | N21: 28168.8 | O21: 44942.49
A22: 17 | B22: IS | C22: 2022-04-19 | D22: 2022-04-27 | E22: long | F22: 14484.62 | G22: 5.5159 | H22: 6.8356 | J22: 1.31934 | K22: =IF(J22>0,"прибыль",IF(J22<0,"убыток","ноль")) -> прибыль | L22: =IF(C22="",L21,IF(J22<0,L21+1,0)) -> 0 | M22: 1319.34 | N22: 19110.09 | O22: 64052.58
A23: 18 | B23: IS | C23: 2022-04-27 | D23: 2022-05-05 | E23: long | F23: 10194.65 | G23: 5.5159 | H23: 7.6313 | I23: да | J23: 1.91371 | K23: =IF(J23>0,"прибыль",IF(J23<0,"убыток","ноль")) -> прибыль | L23: =IF(C23="",L22,IF(J23<0,L22+1,0)) -> 0 | M23: 1913.71 | N23: 19509.59 | O23: 83562.17
A24: 19 | B24: IS | C24: 2022-05-05 | D24: 2022-06-15 | E24: long | F24: 8123.02 | G24: 6.5125 | H24: 7.4956 | I24: да | J24: 1.07365 | K24: =IF(J24>0,"прибыль",IF(J24<0,"убыток","ноль")) -> прибыль | L24: =IF(C24="",L23,IF(J24<0,L23+1,0)) -> 0 | M24: 1073.65 | N24: 8721.29 | O24: 92283.47
A25: 20 | B25: IS | C25: 2022-06-15 | D25: 2022-07-18 | E25: long | F25: 7561.6 | G25: 6.3663 | H25: 6.9714 | I25: да | J25: 0.26174 | K25: =IF(J25>0,"прибыль",IF(J25<0,"убыток","ноль")) -> прибыль | L25: =IF(C25="",L24,IF(J25<0,L24+1,0)) -> 0 | M25: 261.74 | N25: 1979.16 | O25: 94262.62
A26: 21 | B26: IS | C26: 2022-07-18 | D26: 2022-07-27 | E26: long | F26: 5993.27 | G26: 6.7091 | H26: 8.9693 | J26: 2.25982 | K26: =IF(J26>0,"прибыль",IF(J26<0,"убыток","ноль")) -> прибыль | L26: =IF(C26="",L25,IF(J26<0,L25+1,0)) -> 0 | M26: 2259.82 | N26: 13543.7 | O26: 107806.32
A27: 22 | B27: IS | C27: 2022-07-27 | D27: 2022-10-11 | E27: long | F27: 32541.69 | G27: 7.5788 | H27: 6.6212 | I27: да | J27: -1.11019 | K27: =IF(J27>0,"прибыль",IF(J27<0,"убыток","ноль")) -> убыток | L27: =IF(C27="",L26,IF(J27<0,L26+1,0)) -> 1 | M27: -1110.19 | N27: -36127.37 | O27: 71678.95
A28: 23 | B28: IS | C28: 2022-10-11 | D28: 2022-10-26 | E28: short | F28: 20380.38 | G28: 6.3778 | H28: 5.7217 | J28: 0.6554 | K28: =IF(J28>0,"прибыль",IF(J28<0,"убыток","ноль")) -> прибыль | L28: =IF(C28="",L27,IF(J28<0,L27+1,0)) -> 0 | M28: 655.4 | N28: 13357.38 | O28: 85036.33
A29: 24 | B29: IS | C29: 2022-10-26 | D29: 2022-11-08 | E29: short | F29: 13201.83 | G29: 6.3778 | H29: 6.7698 | I29: да | J29: 0.04116 | K29: =IF(J29>0,"прибыль",IF(J29<0,"убыток","ноль")) -> прибыль | L29: =IF(C29="",L28,IF(J29<0,L28+1,0)) -> 0 | M29: 41.16 | N29: 543.33 | O29: 85579.66
A30: 25 | B30: IS | C30: 2022-11-08 | D30: 2022-12-16 | E30: short | F30: 9502.13 | G30: 6.5448 | H30: 6.8721 | I30: да | J30: -0.02617 | K30: =IF(J30>0,"прибыль",IF(J30<0,"убыток","ноль")) -> убыток | L30: =IF(C30="",L29,IF(J30<0,L29+1,0)) -> 1 | M30: -26.17 | N30: -248.71 | O30: 85330.95
A31: 26 | B31: IS | C31: 2022-12-16 | D31: 2023-02-28 | E31: short | F31: 19432.42 | G31: 4.3041 | H31: 2.8047 | I31: да | J31: 2.21897 | K31: =IF(J31>0,"прибыль",IF(J31<0,"убыток","ноль")) -> прибыль | L31: =IF(C31="",L30,IF(J31<0,L30+1,0)) -> 0 | M31: 2218.97 | N31: 43119.94 | O31: 128450.89
A32: 27 | B32: IS | C32: 2023-02-28 | D32: 2023-04-18 | E32: short | F32: 31389.61 | G32: 3.2305 | H32: 2.3317 | I32: да | J32: 1.30097 | K32: =IF(J32>0,"прибыль",IF(J32<0,"убыток","ноль")) -> прибыль | L32: =IF(C32="",L31,IF(J32<0,L31+1,0)) -> 0 | M32: 1300.97 | N32: 40836.93 | O32: 169287.82
